Workbook

Sheet Introduction
A1: Partner Hosted Foundational Technical Review Partner Hosted Validation Checklist Validity Period: February 2026-August 2026 This version of the checklist was released on February 14th, 2025. The next version of this checklist is expected to be released in August 2025. AWS Partners may continue to use this version of the checklist until November 2025. This workbook is intended to be used by AWS Partners applying for Partner Hosted Foundational Technical Review in order to complete the required self-assessment. Please create a copy of this spreadsheet for your application and complete the requested information on the second tab. For each technical requirement, please indicate if you meet the requirement and provide details in the "Partner Response" column where requested. Once you have completed your self-assessment, attach a completed copy of this spreadsheet along with other required documents (i.e., CIS Benchmark Report, Architecture Diagram) when you request the FTR.
A2: FTR Resources
A3: FTR User Guide
A4: FTR101 – Intro to FTR Video
A5: FTR201- Partner-Hosted SaaS on AWS Video
A6: FTR Calibration Guide
A8: Dear AWS Partners, We've streamlined the Foundational Technical Review (FTR) process to make it even more partner-friendly. If you conducted the FTR or Technical Baseline Review (TBR) process two years ago, we kindly request that you revisit this review to ensure alignment with the latest requirements. The new FTR self-assessment checklist has been simplified, featuring straightforward yes/no questions that allow you to easily grasp AWS expectations. We encourage you to complete this self-assessment checklist with the available information about your AWS architecture and submit it through AWS Partner Central. Our dedicated PSA (Partner Solutions Architect) team is ready to review your response and offer guidance where needed to help you secure FTR approval. Thank you for your ongoing partnership, and we look forward to continuing our journey together.
A10: Version | B10: 2026.1

Sheet Partner Hosted FTR Requirements
A1: Partner Hosted FTR Requirements The following requirements apply to any components hosted and operated by the AWS Partner in their own AWS account. The controls which include a Center for Internet Security(CIS) benchmark ID are covered by the automated AWS account scan, please attach your CIS Benchmark report to prevent any delays in processing your FTR request. The cells highlighted in grey are not editable, the field is auto generated.
A2: FTR Percent Complete | B2: =B4/E4 -> 0
A3: Provisional FTR Outcome | C3: Pass / Fail / Further Review
A4: Controls Met | B4: =COUNTIF(D:D,"Pass") -> 0 | C4: Controls Not Met | E4: =COUNTIF(D:D, "Fail") -> 44
A5: ID | B5: Requirement Description | C5: Met? (Yes/No/NA) | D5: Approval Requirements | E5: Partner Response / Guidance | F5: AWS Solution Architect Comments ONLY
A7: CIS Benchmark Report | B7: Have you completed a CIS benchmark report and do you plan to attach it in the FTR request form in Partner Central? | C7: <select> | E7: =IF(C7="No",'Supporting Information Required'!C2,IF(C7="Yes",'Supporting Information Required'!D2,IF(C7="NA","Ok","")))
A8: CIS Benchmark Report | B8: Which version of the CIS Benchmark report did you submit? | C8: <select> | E8: =IF(C8="CIS v5.0",'Supporting Information Required'!C3,IF(C8="CIS v3.0",'Supporting Information Required'!D3,IF(C7="NA","Ok","")))
A9: General Availability | B9: All solutions submitted for FTR must be either: • Generally Available (GA), or • Available for customers to purchase Does your solution meet this criteria? | C9: <select> | E9: =IF(C9="No",'Supporting Information Required'!C4,IF(C9="Yes",'Supporting Information Required'!D4,IF(C9="NA","Ok","")))
A11: Partner Hosted
A13: HOST-001 | B13: Confirm your hosting model. To qualify for FTR your product must run entirely on AWS. This includes the application and control planes. The application plane can run in the seller's AWS account, the buyer's AWS account, or both. For more information, refer to the Control plane vs. application plane (https://docs.aws.amazon.com/whitepapers/latest/saas-architecture-fundamentals/control-plane-vs.-application-plane.html) whitepaper. Third-party services used by the product to transmit, store, or process application data must also run entirely on AWS —except for content delivery networks (CDNs), domain name systems (DNSs), and corporate identity providers (IdPs). Agents or gateways used by the product for security, monitoring, data replication, or migration can run on buyer-owned environments outside AWS, including on premises, but must send data only to AWS for storage and analysis. You must include an architecture diagram for review. For more information, refer to Architecture diagram (https://docs.aws.amazon.com/marketplace/latest/userguide/saas-guidelines.html#saas-architecture). Listing on Marketplace is not required to complete a FTR. | C13: =IF(OR(C14="<select>",C15="<select>", C16="<select>"), "", IF(D13="Fail", "No", IF(D13="Pass", "Yes"))) | D13: =IF(OR( AND(C14="Yes", C15="Yes", C16="Yes")), "Pass","Fail") -> Fail
A14: HOST-001.1 | B14: Is your entire application infrastructure hosted on AWS? | C14: <select> | D14: =IF(C14="No",'Supporting Information Required'!C7,IF(C14="Yes",'Supporting Information Required'!D7, "")) | E14: =IF(C14="No",'Supporting Information Required'!C7,IF(C14="Yes",'Supporting Information Required'!D7,IF(C14="NA","Ok","")))
A15: HOST-001.2 | B15: Are all of the third-party services used by your application also hosted on AWS? If you are unsure, please verify with your third-party service provider where they are hosted. | C15: <select> | E15: =IF(C15="No",'Supporting Information Required'!D8,IF(C15="Yes",'Supporting Information Required'!C8,IF(C15="Not-Applicable",'Supporting Information Required'!E8,"")))
A16: HOST-001.3 | B16: As part of your FTR submission, please confirm you will include an architecture diagram that meets all the specified criteria here (https://docs.aws.amazon.com/marketplace/latest/userguide/saas-guidelines.html#arch-diagram). | C16: <select> | D16: =IF(C16="No",'Supporting Information Required'!C12,IF(C16="Yes",'Supporting Information Required'!D12, "")) | E16: =IF(C16="No",'Supporting Information Required'!C9,IF(C16="Yes",'Supporting Information Required'!D9,IF(C16="Not-Applicable",'Supporting Information Required'!E9,"")))
A18: Support Level
A20: SUP-001 | B20: Subscribe to the AWS Business Support tier (or higher) for all production AWS accounts or have an action plan to handle issues which require help from AWS Support. It is recommended that you subscribe to the AWS Business Support tier or higher for all of your AWS production accounts. For more information, refer to Compare AWS Support Plans. If you don't have premium support, you must have an action plan to handle issues which require help from AWS Support. AWS Support provides a mix of tools and technology, people, and programs designed to proactively help you optimize performance, lower costs, and innovate faster. AWS Business Support (https://aws.amazon.com/premiumsupport/plans/business/) provides additional benefits including access to AWS Trusted Advisor (https://aws.amazon.com/premiumsupport/technology/trusted-advisor/) and AWS Personal Health Dashboard (https://aws.amazon.com/premiumsupport/technology/personal-health-dashboard) and faster response times. | C20: =IF(C21="<select>", "", IF(D20="Pass", "Yes", IF( D20="Fail", "No"))) | D20: =IF(OR(C21="Yes",AND(E20<>"",C21="NO")), "Pass","Fail") -> Fail
A21: SUP-001.1 | B21: Is your support tier Business or higher on all productions AWS accounts? | C21: <select> | D21: =IF(C21="No",'Supporting Information Required'!C12,IF(C21="Yes",'Supporting Information Required'!D12,IF(C21="NA",'Supporting Information Required'!E12,""))) | E21: =IF(C21="No",'Supporting Information Required'!C12,IF(C21="Yes",'Supporting Information Required'!D12,IF(C21="NA",'Supporting Information Required'!E12,"")))
A23: Architecture Review
A25: WAFR-001 | B25: Conduct periodic architecture reviews (minimum once every year). Conduct periodic architecture reviews of your production workload (at least once per year) using a documented architectural standard that includes AWS-specific best practices. If you have an internally defined standard for your AWS workloads, we recommend you use it for these reviews. If you do not have an internal standard, we recommend you use the AWS Well-Architected Framework (https://aws.amazon.com/architecture/well-architected/). | C25: =IF(C26="<select>", "", IF(D25="Pass", "Yes", IF( D25="Fail", "No"))) | D25: =IF(AND(C26="Yes",C27="Yes"), "Pass","Fail") -> Fail
A26: WAFR-001.1 | B26: Do you do periodic architecture reviews? | C26: <select> | D26: =IF(C26="No",'Supporting Information Required'!C16,IF(C26="Yes",'Supporting Information Required'!D16,IF(C26="NA",'Supporting Information Required'!E16,""))) | E26: =IF(C26="No",'Supporting Information Required'!C16,IF(C26="Yes",'Supporting Information Required'!D16,IF(C26="NA",'Supporting Information Required'!E16,"")))
A27: WAFR-001.2 | B27: Have you done an architecture review in the last year? | C27: <select> | E27: =IF(C27="No",'Supporting Information Required'!C17,IF(C27="Yes",'Supporting Information Required'!D17,IF(C27="NA",'Supporting Information Required'!E17,"")))
A28: WAFR-002 | B28: Review the AWS Shared Responsibility Model for Security (https://docs.aws.amazon.com/whitepapers/latest/aws-risk-and-compliance/shared-responsibility-model.html) and the AWS Shared Responsibility Model for Resiliency (https://docs.aws.amazon.com/whitepapers/latest/disaster-recovery-workloads-on-aws/shared-responsibility-model-for-resiliency.html). Ensure that your product’s architecture and operational processes address the customer responsibilities defined in these models. We recommend you to use AWS Resilience Hub (https://aws.amazon.com/resilience-hub/) to ensure your workload resiliency posture meets your targets and to provide you with operational procedures you may use to address the customer responsibilities. | C28: =IF(C29="<select>", "",C29) | D28: =IF(C29="Yes","Pass","Fail") -> Fail
A29: WAFR-002.1 | B29: Have you reviewed the AWS Shared Responsibility Models for Security and Resiliency? | C29: <select> | D29: =IF(C29="No",'Supporting Information Required'!C19,IF(C29="Yes",'Supporting Information Required'!D19,IF(C29="NA",'Supporting Information Required'!E19,""))) | E29: =IF(C29="No",'Supporting Information Required'!C19,IF(C29="Yes",'Supporting Information Required'!D19,IF(C29="NA",'Supporting Information Required'!E19,"")))
A31: AWS root account
A32: These requirements apply only if you have a password set for your root users. If you are using AWS Organizations to create AWS accounts and don’t request root user passwords, these requirements don’t apply.
A34: ARC-001 | B34: Use root user only by exception. The root user has unlimited access to your account and its resources, and using it only by exception helps protect your AWS resources. The AWS root user must not be used for everyday tasks, even administrative ones. Instead, adhere to the best practice (https://docs.aws.amazon.com/IAM/latest/UserGuide/best-practices.html#create-iam-users) of using the root user only to create your first AWS Identity and Access Management (IAM) user. Then securely lock away the root user credentials and use them to perform only a few accounts and service management tasks. To view the tasks that require you to sign in as the root user, see AWS Tasks That Require Root User (https://docs.aws.amazon.com/general/latest/gr/aws_tasks-that-require-root.html). FTR does not require you to actively monitor root usage. | C34: =IF(C35="<select>", "", IF(D34="Pass", "Yes", IF( D34="Fail", "No"))) | D34: =IF(AND(OR(C35="Yes",C35="NA", C35="NO"),OR(E34<>"",E35="Okay. You can optionally add notes or comments in the 'Partner Response' cell in white above.")), "Pass","Fail") -> Fail
A35: ARC-001.1 | B35: Is the AWS root account used for any OTHER tasks than the ones listed in this link? https://docs.aws.amazon.com/accounts/latest/reference/root-user-tasks.html | C35: <select> | D35: =IF(C35="No",'Supporting Information Required'!C22,IF(C35="Yes",'Supporting Information Required'!D22, "")) | E35: =IF(C35="No",'Supporting Information Required'!C22,IF(C35="Yes",'Supporting Information Required'!D22,IF(C35="NA","Ok","")))
A36: ARC-004 | B36: Remove access keys for the root user (CIS Control, see mapping reference in Row 8 above). Programmatic access to AWS APIs should never use the root user. It is best not to generate static an access key for the root user. If one already exists, you should transition any processes using that key to use temporary access keys from an AWS Identity and Access Management (IAM) role, or, if necessary, static access keys from an IAM user. | C36: =IF(C37="<select>", "", IF(C37="Yes", "No", IF( C37="No", "Yes"))) | D36: =IF(C37="No", "Pass", "Fail") -> Fail
A37: ARC-004.1 | B37: Do you have access keys provisioned for the root user? | C37: <select> | D37: =IF(C37="No",'Supporting Information Required'!C24,IF(C37="Yes",'Supporting Information Required'!D24)) -> FALSE | E37: =IF(C37="No",'Supporting Information Required'!C24,IF(C37="Yes",'Supporting Information Required'!D24,IF(C37="NA","Ok","")))
A38: ARC-005 | B38: Develop incident management plans. An incident management plan is critical to respond, mitigate, and recover from the potential impact of security incidents. An incident management plan is a structured process for identifying, remediating, and responding in a timely matter to security incidents. An effective incident management plan must be continually iterated upon, remaining current with your cloud operations goal. For more information on developing incident management plan please see Develop incident management plans (https://docs.aws.amazon.com/wellarchitected/latest/security-pillar/sec_incident_response_develop_management_plans.html) | C38: =IF(C39="<select>", "",C39) | D38: =IF(C39="Yes", "Pass","Fail") -> Fail
A39: ARC-005.1 | B39: Is there a documented process to respond, mitigate, and recover from security incidents? | C39: <select> | D39: =IF(C39="No",'Supporting Information Required'!C26,IF(C39="Yes",'Supporting Information Required'!D26, "")) | E39: =IF(C39="No",'Supporting Information Required'!C26,IF(C39="Yes",'Supporting Information Required'!D26,IF(C39="NA","Ok","")))
A41: Communications from AWS
A43: ACOM-001 | B43: Configure AWS account contacts (CIS Control, see mapping reference in Row 8 above). If an account is not managed by AWS Organizations (https://d2jzdts88nec9c.cloudfront.net/ftr.concept.awsorganizations.en.html), alternate account contacts help AWS get in contact with the appropriate personnel if needed. Configure the account’s alternate contacts (http://docs.aws.amazon.com/awsaccountbilling/latest/aboutv2/manage-account-payment.html#account-contacts) to point to a group rather than an individual. For example, create separate email distribution lists for billing, operations, and security and configure these as Billing, Security, and Operations contacts in each active AWS account. This ensures that multiple people will receive AWS notifications and be able to respond, even if someone is on vacation, changes roles, or leaves the company. | C43: =IF(C44="<select>", "",C44) | D43: =IF(OR(C44="Yes", C44="Na"),"Pass","Fail") -> Fail
A44: ACOM-001.1 | B44: Are AWS alternate contacts configured? | C44: <select> | D44: =IF(C44="No",'Supporting Information Required'!C31,IF(C44="Yes",'Supporting Information Required'!D31, "")) | E44: =IF(C44="No",'Supporting Information Required'!C31,IF(C44="Yes",'Supporting Information Required'!D31,IF(C44="NA","Ok","")))
A45: ACOM-002 | B45: Set account contact information including the root user email address to email addresses and phone numbers owned by your company. Using company owned email addresses and phone numbers for contact information enables you to access them even if the individuals whom they belong to are no longer with your organization. | C45: =IF(C46="<select>", "",C46) | D45: =IF(OR(C46="Yes", C46="Na"), "Pass","Fail") -> Fail
A46: ACOM-002.1 | B46: Are all of the communications emails including the root user, are configured to use company emails (e.g. no personal / Gmail addresses)? | C46: <select> | D46: =IF(C46="No",'Supporting Information Required'!C33,IF(C46="Yes",'Supporting Information Required'!E33, "")) | E46: =IF(C46="No",'Supporting Information Required'!C33,IF(C46="Yes",'Supporting Information Required'!D33,IF(C46="NA","Ok","")))
A48: Identity and Access Management
A49: The requirements in this section pertain to how you manage identities and access for your solution. This includes both AWS Identity and Access Management (IAM) resources as well as other identity providers and access mechanisms (e.g. access management for end users of your product, handing of database credentials, intra-service access control, etc.)
A50: The requirements in this section pertain to how you manage identities and access for your solution. This includes both AWS Identity and Access Management (IAM) resources as well as other identity providers and access mechanisms (for example, access management for end users of your product, handing of database credentials, and intra-service access control.)
A52: IAM-001 | B52: Enable multi-factor authentication (MFA) for all Human Identities with AWS access (CIS Control, see mapping reference in Row 8 above). You must require any human identities to authenticate using MFA before accessing your AWS accounts. Typically, this means enabling MFA within your corporate identity provider. If you have existing legacy IAM users you must enable MFA for console access for those principals as well. Enabling MFA for IAM users provides an additional layer of security. With MFA, users have a device that generates a unique authentication code (a one-time password, or OTP). Users must provide both their normal credentials (user name and password) and the OTP. The MFA device can either be a special piece of hardware, or it can be a virtual device (for example, it can run in an app on a smartphone). Please note that machine identities do not require MFA. | C52: =IF(C53="<select>", "", IF(D52="Fail", "No", IF(D52="Pass", "Yes"))) | D52: =IF(C53="Yes","Pass","Fail") -> Fail
A53: IAM-001.1 | B53: Is MFA enabled for all human users to access AWS accounts? (This may be enabled in your IDP to federate access) | C53: <select> | D53: =IF(C53="No",'Supporting Information Required'!C39,IF(C53="Yes",'Supporting Information Required'!D39,IF(C53="NA",'Supporting Information Required'!E39,""))) | E53: =IF(C53="No",'Supporting Information Required'!C39,IF(C53="Yes",'Supporting Information Required'!D39,IF(C53="NA",'Supporting Information Required'!E39,"")))
...

Sheet FTR Results Summary
A1: Partner-hosted FTR Results Summary
A2: ID | B2: Requirement Description | C2: Met? | D2: Partner Response | E2: Guidance
A4: CIS Benchmark Report | B4: Have you completed a CIS benchmark report and do you plan to attach it in the FTR request form in Partner Central? | C4: ='Partner Hosted FTR Requirements'!C7 -> <select> | E4: ='Partner Hosted FTR Requirements'!E7
A5: HOST-001 | B5: Confirm your hosting model. | C5: ='Partner Hosted FTR Requirements'!C13 | D5: =IF('Partner Hosted FTR Requirements'!E13="", "", 'Partner Hosted FTR Requirements'!E13) | E5: ='Partner Hosted FTR Requirements'!E14
A6: SUP-001 | B6: Subscribe to the AWS Business Support tier (or higher) for all production AWS accounts or have an action plan to handle issues which require help from AWS Support. | C6: ='Partner Hosted FTR Requirements'!C20 | D6: =IF('Partner Hosted FTR Requirements'!E20="", "", 'Partner Hosted FTR Requirements'!E20) | E6: ='Partner Hosted FTR Requirements'!E21
A7: WAFR-001 | B7: Conduct periodic architecture reviews (minimum once every year). | C7: ='Partner Hosted FTR Requirements'!C25 | D7: =IF('Partner Hosted FTR Requirements'!E25="", "", 'Partner Hosted FTR Requirements'!E25) | E7: ='Partner Hosted FTR Requirements'!E26& CHAR(10) &'Partner Hosted FTR Requirements'!E27
A8: WAFR-002 | B8: Review the AWS Shared Responsibility Models for Security and Resiliency. | C8: ='Partner Hosted FTR Requirements'!C28 | D8: =IF('Partner Hosted FTR Requirements'!E28="", "", 'Partner Hosted FTR Requirements'!E28) | E8: ='Partner Hosted FTR Requirements'!E29
A9: ARC-001 | B9: Use root user only by exception. | C9: ='Partner Hosted FTR Requirements'!C34 | D9: =IF('Partner Hosted FTR Requirements'!E34="", "", 'Partner Hosted FTR Requirements'!E34) | E9: ='Partner Hosted FTR Requirements'!E35
A10: ARC-004 | B10: Remove access keys for the root user (CIS 1.4/Security Control IAM.4). | C10: ='Partner Hosted FTR Requirements'!C36 | D10: =IF('Partner Hosted FTR Requirements'!E36="", "", 'Partner Hosted FTR Requirements'!E36) | E10: ='Partner Hosted FTR Requirements'!E37
A11: ARC-005 | B11: Please create a documented procedure for responding to, mitigating, and recovering from security incidents before to submitting the FTR. | C11: ='Partner Hosted FTR Requirements'!C38 | E11: ='Partner Hosted FTR Requirements'!E39
A12: ACOM-001 | B12: Configure AWS account contacts (CIS 1.2/Security Control Account.1). | C12: ='Partner Hosted FTR Requirements'!C43 | D12: =IF('Partner Hosted FTR Requirements'!E43="", "", 'Partner Hosted FTR Requirements'!E43) | E12: ='Partner Hosted FTR Requirements'!E44
A13: ACOM-002 | B13: Set account contact information including the root user email address to email addresses and phone numbers owned by your company. | C13: ='Partner Hosted FTR Requirements'!C45 | D13: =IF('Partner Hosted FTR Requirements'!E45="", "", 'Partner Hosted FTR Requirements'!E45) | E13: ='Partner Hosted FTR Requirements'!E46
A14: IAM-001 | B14: Enable multi-factor authentication (MFA) for all Human Identities with AWS access (CIS 1.10/Security Control IAM.5). | C14: ='Partner Hosted FTR Requirements'!C52 | D14: =IF('Partner Hosted FTR Requirements'!E52="", "", 'Partner Hosted FTR Requirements'!E52) | E14: ='Partner Hosted FTR Requirements'!E53
A15: IAM-002 | B15: Monitor and secure static AWS Identity and Access Management (IAM) credentials (CIS 1.14/Security Control IAM.3). | C15: ='Partner Hosted FTR Requirements'!C54 | D15: =IF('Partner Hosted FTR Requirements'!E54="", "", 'Partner Hosted FTR Requirements'!E54) | E15: ='Partner Hosted FTR Requirements'!E55 & CHAR(10) & 'Partner Hosted FTR Requirements'!E56 & CHAR(10) & 'Partner Hosted FTR Requirements'!E57 & CHAR(10) & 'Partner Hosted FTR Requirements'!E58
A16: IAM-003 | B16: Use strong password policy (CIS 1.8/Security Control IAM.15 and CIS 1.9/Security Control IAM.16). | C16: ='Partner Hosted FTR Requirements'!C59 | D16: =IF('Partner Hosted FTR Requirements'!E59="", "", 'Partner Hosted FTR Requirements'!E59) | E16: ='Partner Hosted FTR Requirements'!E60
A17: IAM-004 | B17: Create individual identities (no shared credentials) for anyone who needs AWS access. | C17: ='Partner Hosted FTR Requirements'!C61 | D17: =IF('Partner Hosted FTR Requirements'!E61="", "", 'Partner Hosted FTR Requirements'!E61) | E17: ='Partner Hosted FTR Requirements'!E62
A18: IAM-005 | B18: Use IAM roles and its temporary security credentials to provide access to third parties. | C18: ='Partner Hosted FTR Requirements'!C63 | D18: =IF('Partner Hosted FTR Requirements'!E63="", "", 'Partner Hosted FTR Requirements'!E63) | E18: ='Partner Hosted FTR Requirements'!E64& CHAR(10) &'Partner Hosted FTR Requirements'!E66
A19: IAM-006 | B19: Grant least privilege access (CIS 1.16/Security Control IAM.1). | C19: ='Partner Hosted FTR Requirements'!C67 | D19: =IF('Partner Hosted FTR Requirements'!E67="", "", 'Partner Hosted FTR Requirements'!E67) | E19: ='Partner Hosted FTR Requirements'!E68
A20: IAM-007 | B20: Manage access based on life cycle. | C20: ='Partner Hosted FTR Requirements'!C69 | D20: =IF('Partner Hosted FTR Requirements'!E69="", "", 'Partner Hosted FTR Requirements'!E69) | E20: ='Partner Hosted FTR Requirements'!E70
A21: IAM-008 | B21: Audit identities quarterly. | C21: ='Partner Hosted FTR Requirements'!C71 | D21: =IF('Partner Hosted FTR Requirements'!E71="", "", 'Partner Hosted FTR Requirements'!E71) | E21: ='Partner Hosted FTR Requirements'!E72
A22: IAM-009 | B22: Do not embed credentials in application code. | C22: ='Partner Hosted FTR Requirements'!C73 | D22: =IF('Partner Hosted FTR Requirements'!E73="", "", 'Partner Hosted FTR Requirements'!E73) | E22: ='Partner Hosted FTR Requirements'!E74
A23: IAM-010 | B23: Store secrets securely. | C23: ='Partner Hosted FTR Requirements'!C75 | D23: =IF('Partner Hosted FTR Requirements'!E75="", "", 'Partner Hosted FTR Requirements'!E75) | E23: ='Partner Hosted FTR Requirements'!E76
A24: IAM-011 | B24: Encrypt all end user/customer credentials and hash passwords at rest. | C24: ='Partner Hosted FTR Requirements'!C77 | D24: =IF('Partner Hosted FTR Requirements'!E77="", "", 'Partner Hosted FTR Requirements'!E77) | E24: ='Partner Hosted FTR Requirements'!E78
A25: IAM-012 | B25: Use temporary credentials | C25: ='Partner Hosted FTR Requirements'!C79 | D25: =IF('Partner Hosted FTR Requirements'!E79="", "", 'Partner Hosted FTR Requirements'!E79) | E25: ='Partner Hosted FTR Requirements'!E80
A26: SECOPS-001 | B26: Perform vulnerability management. | C26: ='Partner Hosted FTR Requirements'!C85 | D26: =IF('Partner Hosted FTR Requirements'!E85="", "", 'Partner Hosted FTR Requirements'!E85) | E26: ='Partner Hosted FTR Requirements'!E86
A27: NETSEC-001 | B27: Implement the least permissive rules for all Amazon EC2 security groups (CIS 5.2/Security Control EC2.53), (CIS 5.3/Security Control EC2.54), (CIS 5.4/Security Control EC2.2). | C27: ='Partner Hosted FTR Requirements'!C90 | D27: =IF('Partner Hosted FTR Requirements'!E90="", "", 'Partner Hosted FTR Requirements'!E90) | E27: ='Partner Hosted FTR Requirements'!E91& CHAR(10) &'Partner Hosted FTR Requirements'!E92& CHAR(10)
A28: NETSEC-002 | B28: Restrict resources in public subnets. | C28: ='Partner Hosted FTR Requirements'!C93 | D28: =IF('Partner Hosted FTR Requirements'!E93="", "", 'Partner Hosted FTR Requirements'!E93) | E28: ='Partner Hosted FTR Requirements'!E94
A29: BAR-001 | B29: Configure automatic data backups. | C29: ='Partner Hosted FTR Requirements'!C98 | D29: =IF('Partner Hosted FTR Requirements'!E98="", "", 'Partner Hosted FTR Requirements'!E98) | E29: ='Partner Hosted FTR Requirements'!E99
A30: BAR-002 | B30: Periodically recover data to verify the integrity of your backup process. | C30: ='Partner Hosted FTR Requirements'!C100 | D30: =IF('Partner Hosted FTR Requirements'!E100="", "", 'Partner Hosted FTR Requirements'!E100) | E30: ='Partner Hosted FTR Requirements'!E101& CHAR(10) &'Partner Hosted FTR Requirements'!E102
A31: RES-001 | B31: Define a Recovery Point Objective (RPO). | C31: ='Partner Hosted FTR Requirements'!C106 | D31: =IF('Partner Hosted FTR Requirements'!E106="", "", 'Partner Hosted FTR Requirements'!E106) | E31: ='Partner Hosted FTR Requirements'!E107
A32: RES-002 | B32: Establish a Recovery Time Objective (RTO). | C32: ='Partner Hosted FTR Requirements'!C108 | D32: =IF('Partner Hosted FTR Requirements'!E108="", "", 'Partner Hosted FTR Requirements'!E108) | E32: ='Partner Hosted FTR Requirements'!E109
A33: RES-004 | B33: Resiliency Testing | C33: ='Partner Hosted FTR Requirements'!C110 | D33: =IF('Partner Hosted FTR Requirements'!E110="", "", 'Partner Hosted FTR Requirements'!E110) | E33: ='Partner Hosted FTR Requirements'!E111
A34: RES-005 | B34: Communicate customer responsibilities for resilience. | C34: ='Partner Hosted FTR Requirements'!C112 | D34: =IF('Partner Hosted FTR Requirements'!E112="", "", 'Partner Hosted FTR Requirements'!E112) | E34: ='Partner Hosted FTR Requirements'!E113
A35: RES-006 | B35: Architect your product to meet availability targets and uptime service level agreements (SLAs). | C35: ='Partner Hosted FTR Requirements'!C114 | D35: =IF('Partner Hosted FTR Requirements'!E114="", "", 'Partner Hosted FTR Requirements'!E114) | E35: ='Partner Hosted FTR Requirements'!E115& CHAR(10) &'Partner Hosted FTR Requirements'!E116
A36: RES-007 | B36: Define a customer communication plan for outages. | C36: ='Partner Hosted FTR Requirements'!C117 | D36: =IF('Partner Hosted FTR Requirements'!E117="", "", 'Partner Hosted FTR Requirements'!E117) | E36: ='Partner Hosted FTR Requirements'!E118
A37: S3-001 | B37: Review all Amazon S3 buckets to determine appropriate access levels. | C37: ='Partner Hosted FTR Requirements'!C122 | D37: =IF('Partner Hosted FTR Requirements'!E122="", "", 'Partner Hosted FTR Requirements'!E122) | E37: ='Partner Hosted FTR Requirements'!E123
A38: CAA-001 | B38: Use cross-account roles to access customer AWS accounts. | C38: ='Partner Hosted FTR Requirements'!C128 | D38: =IF('Partner Hosted FTR Requirements'!E128="", "", 'Partner Hosted FTR Requirements'!E128) | E38: ='Partner Hosted FTR Requirements'!E129
A39: CAA-007 | B39: Provide guidance or an automated setup mechanism (for example, an AWS CloudFormation template) for creating cross-account roles with the minimum required privileges. | C39: ='Partner Hosted FTR Requirements'!C130 | D39: =IF('Partner Hosted FTR Requirements'!E130="", "", 'Partner Hosted FTR Requirements'!E130) | E39: ='Partner Hosted FTR Requirements'!E131
A40: CAA-002 | B40: Use an external ID with cross-account roles to access customer accounts. | C40: ='Partner Hosted FTR Requirements'!C132 | D40: =IF('Partner Hosted FTR Requirements'!E132="", "", 'Partner Hosted FTR Requirements'!E132) | E40: ='Partner Hosted FTR Requirements'!E133
A41: CAA-004 | B41: Use a value you generate (not something provided by the customer) for the external ID. | C41: ='Partner Hosted FTR Requirements'!C134 | D41: =IF('Partner Hosted FTR Requirements'!E134="", "", 'Partner Hosted FTR Requirements'!E134) | E41: ='Partner Hosted FTR Requirements'!E135
...

Sheet Explanation
A1: FTR Calibration Guide This calibration guide is intended for AWS partners who have applied or are interested in the Foundational Technical Review for Partner Hosted Solution. The calibration guide provides clarity on the requirements, criteria for meeting the requirements, and why the requirements are important. It helps partner improve application quality and reduce cycle time during the technical validation process. Additionally, partners can use the best practices in this technical guide to improve their Software Offering.
A2: ID | B2: Requirement Description | C2: Why is this important? | D2: Criteria for passing this control | E2: Examples of acceptable Criteria | F2: Examples of unacceptable practice | G2: Technical enablement resources
A3: HOST-001 | B3: Confirm your hosting model. | C3: This requirement is essential for the FTR validation process, which evaluates how effectively the SaaS solution implements AWS best practices for security, reliability, and operational excellence within the AWS environment. To qualify for AWS Partner Network (APN) programs, your application must be hosted on AWS infrastructure. | D3: AWS Marketplace requires Software-as-a-Service (SaaS) infrastructure partners to host their critical infrastructure components on AWS. The only permitted exceptions are Content Delivery Networks (CDN), Domain Name Systems (DNS), and Identity Providers (IdP). Hosting critical components on another public cloud or accessing third party services and using LLM's outside AWS will disqualify the solution for FTR. Partner must provide an architecture diagram which clearly details the components of the solution. You can refer to the architecture guidelines on the architecture diagram section of the AWS Marketplace seller guide(https://docs.aws.amazon.com/marketplace/latest/userguide/saas-guidelines.html#saas-architecture). When a partner's solution migrates workloads to AWS, the partner must attest in the FTR checklist that AWS is the sole migration target. For solutions that support replication to other environments, partners must remove AWS-specific replication features and publish them as a separate product to qualify for FTR. | E3: • Control plane and application plane are running on AWS • All critical components are running on AWS other than CDN, DNS, IdP | F3: • Application entirely runs on another public cloud and integrates with AWS • Core components running on another public cloud • Control plane running on another public cloud | G3: • SaaS product guidelines for AWS Marketplace https://docs.aws.amazon.com/marketplace/latest/userguide/saas-guidelines.html#saas-architecture)
A4: SUP-001 | B4: Subscribe to the AWS Business Support tier (or higher including AWS Partner-led Support) for all production AWS accounts or have an action plan to handle issues which require help from AWS Support | C4: Partners may encounter issues which will require AWS support to resolve. In addition, AWS Support provides a mix of tools and technology, people, and programs designed to proactively help Partners optimize performance, lower costs, and innovate faster. AWS Business Support (https://aws.amazon.com/premiumsupport/plans/business/) provides additional benefits including access to AWS Trusted Advisor (https://aws.amazon.com/premiumsupport/technology/trusted-advisor/) and AWS Personal Health Dashboard (https://aws.amazon.com/premiumsupport/technology/aws-health/) and faster response times. | D4: • Partner has AWS Business or Enterprise support OR Partner Led Support • Partners has an action plan to handle issues which require AWS support. This may include having a long SLA with customers which allows them to use developer support and a strategy to enable support when they have their first incident which require AWS support. | E4: • Partner either subscribes to AWS Premium support or have an action plan to handle issues which require AWS Support. | F4: • Partner does not subscribe to premium support and does not have an action plan to handle issues which require AWS Support. | G4: • Business Support (https://aws.amazon.com/premiumsupport/plans/business/) • Enabling AWS Business Support (https://repost.aws/knowledge-center/sign-up-support) • AWS Trusted Advisor (https://aws.amazon.com/premiumsupport/technology/trusted-advisor/) • AWS Personal Health Dashboard (https://aws.amazon.com/premiumsupport/technology/aws-health/)
A5: WAFR-001 | B5: Conduct periodic architecture reviews (minimum once every year). | C5: Over time application architectures evolve as new features are implemented. It is important to periodically validate that all architecture best practices are followed and the architecture is fit for purpose. | D5: Partner has conducted at least one architecture review within the year prior to FTR review and has a process in place for periodic architecture review. | E5: • Partner conducts periodic architecture review using an internally defined review process or WAFR. | F5: • Partner does not have a process to do periodic architecture review. | G5: • AWS Well Architected (https://aws.amazon.com/architecture/well-architected/)
A6: WAFR-002 | B6: Review the AWS Shared Responsibility Models for Security and Resiliency. | C6: AWS is responsible for resiliency of the infrastructure that runs all of the services offered in the AWS Cloud. This infrastructure comprises of the hardware, software, networking, and facilities that run AWS Cloud services. Partner is responsible for selecting appropriate services and configuration to meet their resiliency requirements. It is important for Partners to understand what they are responsible for and address them. | D6: Partner must have reviewed AWS Shared Responsibility Model for Security and the AWS Shared Responsibility Model for Resiliency before the FTR review and attest to it. | E6: • Partner can confirm that they have reviewed and understood the shared responsibility model. | F6: • No confirmation | G6: • AWS Shared Responsibility Model for Security (https://docs.aws.amazon.com/whitepapers/latest/aws-risk-and-compliance/shared-responsibility-model.html) • AWS Shared Responsibility Model for Resiliency (https://docs.aws.amazon.com/whitepapers/latest/disaster-recovery-workloads-on-aws/shared-responsibility-model-for-resiliency.html)
A7: ARC-001 | B7: Use root user only by exception. | C7: The root user has unlimited access to your account and its resources. Since the root user is a single user, it is not possible to audit usage if the same is shared to multiple people. Also, since root user has access to billing information as well hence it is critical to limit its usage to minimum. We recommend you centrally secure the root user credentials of AWS accounts managed using AWS Organizations to prevent root user credential recovery and access at scale. | D7: Partner uses the root users for tasks that require root user. The CIS 1.1 in AWS Security Hub require Partners to monitor root usage as well. However, monitoring is not required for FTR. Partners can add a note to the self-assessment sheet if they failed this control in Security Hub because they don’t have monitoring. Monitoring root user activity is not required to pass this control. If you are using AWS Organizations you can follow this link to centralize the root access for your member accounts.(https://docs.aws.amazon.com/IAM/latest/UserGuide/id_root-enable-root-access.html) | E7: • We use AWS Organzations to centrally manage root user credentials for member accounts. By centrally managing we delete the root user crdentials from member accounts in our organization | F7: • Root user is used for routine tasks. Root user is only used by one person for routine tasks. | G7: • Root user tasks (https://docs.aws.amazon.com/accounts/latest/reference/root-user-tasks.html) • AWS Tasks That Require Root User (https://docs.aws.amazon.com/general/latest/gr/aws_tasks-that-require-root.html) • Security best practices in IAM (https://docs.aws.amazon.com/IAM/latest/UserGuide/best-practices.html#create-iam-users)
A8: ARC-002 | B8: Remove access keys for the root user (CIS 1.4/Security Control IAM.4). | C8: The root user has unlimited access to AWS accounts and their resources. A lost/compromised access key for a root user can be used by bad actors to get unlimited access to AWS account. | D8: Partner must not have any access keys set on the root users and should never be using the root user for programmatic access to AWS API’s. | E8: • Root users do not have access keys. | F8: • Partner uses root user access keys to access only CloudWatch service. | G8: • Best practices to protect your account's root user (https://docs.aws.amazon.com/accounts/latest/reference/best-practices-root-user.html)
A9: ARC-003 | B9: Please create a documented procedure for responding to, mitigating, and recovering from security incidents before to submitting the FTR. | C9: An incident management plan is critical to respond, mitigate, and recover from the potential impact of security incidents. An incident management plan is a structured process for identifying, remediating, and responding in a timely matter to security incidents. Developing thorough and clearly defined incident response processes is key to a successful and scalable incident response program. When a security event occurs, clear steps and workflows will help you to respond in a timely manner. You might already have existing incident response processes. Regardless of your current state, it’s important to update, iterate, and test your incident response processes regularly. | D9: Partner must have an incident response plan to recover from root user credential misuse. It should include the steps to reset the root user password. The incident response plan must cover all the areas as mentioned in the example runbook. | E9: • Partner has a documented incident response plan. | F9: • Partner does not have an incident response plan. | G9: • Incident management plans. (https://docs.aws.amazon.com/wellarchitected/latest/security-pillar/sec_incident_response_develop_management_plans.html)
A10: ACOM-001 | B10: Configure AWS account contacts. | C10: AWS uses this contact information to send notifications for events related to security, billing, operation etc. It is critical that these notifications are received by the right individuals and are acted upon in timely fashion. | D10: Partner has alternate contacts set for all AWS accounts which are not managed by AWS Organizations. | E10: • Account contacts are set for all AWS accounts which are not managed by Organization. | F10: • Account contacts are not set for all AWS accounts which are not managed by Organization. | G10: • Alternate contacts (https://docs.aws.amazon.com/awsaccountbilling/latest/aboutv2/manage-account-payment.html#account-contacts)
A11: ACOM-002 | B11: Set account contact information including the root user email address to email addresses and phone numbers owned by your company. | C11: It is important that the Partner owns the email and the phone number so it is not dependent on an employee. If these assets are owned by the employee and they leave, it will make it difficult to access them. | D11: Partner must use an email and a phone number that is owned by Partner (not personal contact information). | E11: • Email and the phone number used to create AWS account is owned by the Partner organization. | F11: • CTOs Gmail account and cell phone number were used to create AWS Account. | G11: • Creating an AWS account (https://docs.aws.amazon.com/accounts/latest/reference/manage-acct-creating.html)
A12: IAM-001 | B12: Enable multi-factor authentication (MFA) for all Human Identities with AWS access (CIS 1.10/Security Control IAM.5). | C12: The use of Multi-Factor Authentication (MFA) for all Human Identifies is important because it significantly enhances security by requiring Partner employees to provide at least two different forms of authentication to verify their identity. This helps protect their AWS environment from unauthorized access even if one authentication factor is compromised. | D12: All Human Identities with AWS Access have MFA enabled. | E12: Partner explains how they have MFA configured for all Human Identities with access to their AWS Environment. “We are coming in with AWS SSO. All our identities are managed on Active Directory. Users register their MFA devices themselves. We have a corporate policy that mandates the use of MFA devices. We are coming in with AWS SSO. All our identities are managed on Active Directory. Users register their MFA devices themselves. We have a corporate policy that mandates the use of MFA devices.” | F12: Partner does not have mandatory MFA configured for all Human Identities with access to their AWS Environment. | G12: • Enabling a virtual multi-factor authentication (MFA) device (console) (https://docs.aws.amazon.com/IAM/latest/UserGuide/id_credentials_mfa_enable_virtual.html) • Enable multi-factor authentication for AWS Managed Microsoft AD (https://docs.aws.amazon.com/directoryservice/latest/admin-guide/ms_ad_mfa.html) • Enable multi-factor authentication for AD Connector (https://docs.aws.amazon.com/directoryservice/latest/admin-guide/ad_connector_mfa.html)
A13: IAM-002 | B13: Monitor and secure static AWS Identity and Access Management (IAM) credentials (CIS 1.14/Security Control IAM.3). | C13: Temporary security credentials are short-term, as the name implies. They can be configured to last for anywhere from a few minutes to several hours. After the credentials expire, AWS no longer recognizes them or allows any kind of access from API requests made with them. Thus, when they expire the user will require new credentials. In case there is a need to use IAM access keys in such scenario, there needs to be a process in place to maintain an inventory of such keys and monitor activity on them using AWS GuardDuty . Additionally, incase a misuse is detected it is preferred to have an SOP in place to take necessary action to avoid any un-necessary downtime/loss to application. | D13: Partner must use temporary IAM credentials whenever possible. In case the same is not possible, partner can consider rotating IAM access keys regularly (recommended at least every 90 days), maintain inventory of static keys to keep track in case there is a misuse. Further, partner should also have a monitoring to detect such misuse and an SOP in place to revoke the credentials in such event. | E13: Partner is able to explain if they are using temporary credentials or how they are rotating any existing IAM Access Keys regularly (maximum every 90 days) “We use temporary credentials and have some IAM Access Keys being used and we make sure to rotate them every 90 days. We are leveraging AWS Config to manage aged access keys and automate their rotation with Lambda.” | F13: Partner is not rotating IAM Access Keys regularly or doesn’t have a defined strategy to ensure its rotation. “We have Access Keys but rotate them twice per year.” | G13: • Rotating Access Keys (https://docs.aws.amazon.com/IAM/latest/UserGuide/id_credentials_access-keys.html#Using_RotateAccessKey) • Automatically rotate IAM user access keys at scale with AWS Organizations and AWS Secrets Manager (https://docs.aws.amazon.com/prescriptive-guidance/latest/patterns/automatically-rotate-iam-user-access-keys-at-scale-with-aws-organizations-and-aws-secrets-manager.html) • Managing aged access keys through AWS Config Remediations. (https://aws.amazon.com/blogs/mt/managing-aged-access-keys-through-aws-config-remediations/) • Temporary security credentials in IAM (https://docs.aws.amazon.com/IAM/latest/UserGuide/id_credentials_temp.html)
... A46: RCVP-001 | B46: Establish a process to ensure that all required compliance standards are met. | C46: Ensuring compliance helps in meeting legal requirements, maintaining reputation, and managing risks effectively. | D46: Partner has a formal process in place to keep themselves updated regarding any compliance standards. | E46: Partner is able to explain which internal processes they have in place to ensure advertised and required compliance standards that apply to their solution are met. <br>... (Details of the processes) | F46: Partner does not have processes to meet the compliance regulations they advertise. | G46: • Cloud Compliance – AWS (https://aws.amazon.com/compliance/) • Compliance FAQs (https://aws.amazon.com/compliance/faq/) • AWS Cloud Security (https://aws.amazon.com/security/)

Sheet Supporting Information Required
A1: Controls ID | B1: Role | C1: Remediations steps if no | D1: Follow-ups if yes | E1: Follow-ups if NA
A2: CIS Benchmark Report | C2: While the CIS benchmark report is optional, not submitting it will prolong the processing time for your FTR request and necessitate a call with an AWS PSA for approval. | D2: Thank you for submitting a CIS Benchmark report along with your FTR request.
A3: CIS Benchmark Report | C3: The following FTR Contols map to the CIS benmark report v5.0: VCL Control : CIS Benchmark Control 1) ARC-004 : CIS 1.3/ IAM.4 2) ACOM-001: CIS 1.2 / Account.1 3) IAM-001 : CIS 1.9 / IAM.5 4) IAM-002 : CIS 1.13 / IAM.3 5) IAM-003 : CIS 1.7 / IAM.15 & CIS 1.8 / IAM.16 6) NETSEC-001: CIS 5.4 / EC2.54 ; CIS 5.3 / EC2.53 ; CIS 5.5 / EC2.2 | D3: The following FTR Contols map to the CIS benmark report v3.0: VCL Control : CIS Benchmark Control 1) ARC-004 : CIS 1.4/ IAM.4 2) ACOM-001: CIS 1.2 / Account.1 3) IAM-001 : CIS 1.10 / IAM.5 4) IAM-002 : CIS 1.14 / IAM.3 5) IAM-003 : CIS 1.8 / IAM.15 & CIS 1.9 / IAM.16 6) NETSEC-001: CIS 5.3 / EC2.54 ; CIS 5.2 / EC2.53 ; CIS 5.4 / EC2.2
A4: General Availability | C4: Please hold off on submitting the FTR until the solution reaches General Available (GA) status for customers. | D4: You may proceed with completing this FTR checklist if the solution is General Available (GA) to customers.
A5: Partner Hosted
A6: HOST-001
A7: HOST-001.1 | C7: Please list all components and edge services that are hosted outside of AWS (in the 'Partner Response' cell in white above.). | D7: Okay. This response confirms that our SaaS product is completely hosted on AWS infrastructure, with both application and control plane components running all within AWS. Using CDN, DNS, and Corporate Identity services from other providers is acceptable.
A8: HOST-001.2 | C8: Okay. This response indicates that your SaaS product operates exclusively on AWS infrastructure without relying on external third-party services or LLMs. Using CDN, DNS, and Corporate Identity services from other providers is acceptable. | D8: Okay. Please list any 3rd party services used by the product to transmit, store, or process customer data
A9: HOST-001.3 | C9: Please note that an architecture diagram is a mandatory component of your FTR submission - without it, your submission will be considered incomplete and cannot be approved. | D9: Okay. Please ensure you include your architecture diagram when submitting your FTR self-assessment. Both components are required for a complete FTR submission.
A10: Support Level
A11: SUP-001
A12: SUP-001.1 | C12: AWS recommends that production accounts use Business support or greater to receive help from AWS support. Otherwise, please specify your action plan to handle issues which require help from AWS support (in the 'Partner Response' cell in white above). | D12: Okay. You can optionally add notes or comments in the 'Partner Response' cell in white above. | E12: Please explain why this control does not apply to the solution (in the partner response cell F12).
A13: Architecture Review
A14: WAFR-000 | C14: Please proceed with completing the remaining FTR checklist. | D14: You are not required to complete the remaining FTR controls. To receive an FTR WAFR waiver please: 1/ Upload the WAR report as part of the FTR submission, along with this self-assessment checklist. 2/ Provide the email address of the AWS employee that conducted your WAFR in the 'Partner Response' cell in white above.
A15: WAFR-001
A16: WAFR-001.1 | C16: Please conduct an architecture review before submitting the FTR. | D16: Okay. You can optionally add notes or comments in the 'Partner Response' cell in white above. | E16: Please explain why this control does not apply to the solution (in the partner response cell F15).
A17: WAFR-001.2 | C17: Please conduct an architecture review before submitting the FTR. | D17: Okay. You can optionally add notes or comments in the 'Partner Response' cell in white above.
A18: WAFR-002 | D18: Okay. You can optionally add notes or comments in the 'Partner Response' cell in white above.
A19: WAFR-002.1 | C19: Please review the AWS Shared Responsibility Model before submitting the FTR. | D19: Okay. You can optionally add notes or comments in the 'Partner Response' cell in white above.
A20: These requirements apply only if you have a password set for your root users. If you are using AWS Organizations to create AWS accounts and don’t request root user passwords, these requirements don’t apply.
A21: ARC-001
A22: ARC-001.1 | C22: Okay. You can optionally add notes or comments in the 'Partner Response' cell in white above. | D22: Please specify use cases when the root account is used (in the 'Partner Response' cell in white above). | E22: Please explain why this control doesn't apply to your solution in the partner response cell (F28).
A23: ARC-002
A24: ARC-002.1 | C24: Optional- please submit a Security Hub report to verify configuration. | D24: Please delete all static access keys for all root user acounts before submitting the FTR. | E24: Please explain why this control doesn't apply to your solution in the partner response cell (F32).
A25: ARC-003
A26: ARC-003.1 | C26: Please create a documented procedure for responding to, mitigating, and recovering from security incidents before to submitting the FTR. | D26: Okay. You can optionally add notes or comments in the 'Partner Response' cell in white above. | E26: Please explain why this control doesn't apply to your solution in the partner response cell (F34).
A28: Communications from AWS
A30: ACOM-001
A31: ACOM-001.1 | C31: Please configure AWS account contacts using distribution list(s) instead of individual user emails. | D31: Okay. You can optionally add notes or comments in the 'Partner Response' cell in white above. | E31: Please explain why this control doesn't apply to your solution in the partner response cell (F39).
A32: ACOM-002
A33: ACOM-002.1 | C33: Please set account information, including all email addresses and phone numbers, to ones owned by the company before submitting the FTR. | D33: Okay. You can optionally add notes or comments in the 'Partner Response' cell in white above. | E33: Please explain why this control doesn't apply to your solution in the partner response cell (F41).
A36: Identity and Access Management
A38: IAM-001
A39: IAM-001.1 | C39: Please enable MFA for all human identities with AWS access before submitting the FTR. | D39: Okay. You can optionally add notes or comments in the 'Partner Response' cell in white above. | E39: Please explain why this control doesn't apply to your solution in the partner response cell (F59).
A40: IAM-002
A41: IAM-002.1 | C41: Please implement credentials rotation to at least every 90 days before submitting the FTR. | D41: Ok - you meet the requirements for this control. You are not required to complete IAM-002.2 - IAM-002.4. | E41: Please explain why this control doesn't apply to your solution in the partner response cell (F61).
A42: IAM-002.2 | C42: Please create an inventory of all static keys and where they are used and remove unused access keys. | D42: Okay. You can optionally add notes or comments in the 'Partner Response' cell in white above.
A43: IAM-002.3 | C43: Please implement monitoring of AWS CloudTrail logs to detect anomalous activity or other potential misuse (e.g. using AWS GuardDuty.) | D43: Okay. You can optionally add notes or comments in the 'Partner Response' cell in white above. | E43: This requirement is N/A since you rotate access keys regularly
A44: IAM-002.4 | C44: Please create a runbook or SOP for revoking credentials in the event you detect misuse. | D44: Okay. You can optionally add notes or comments in the 'Partner Response' cell in white above. | E44: This requirement is N/A since you rotate access keys regularly
A45: IAM-003
...
